<?xml version="1.0" ?>
<!-- =================================================================================== -->
<!-- |    This document was autogenerated by xacro from rpibot.urdf.xacro              | -->
<!-- |    EDITING THIS FILE BY HAND IS NOT RECOMMENDED                                 | -->
<!-- =================================================================================== -->
<robot name="rpibot">
  <material name="white">
    <color rgba="1 1 1 1"/>
  </material>
  <material name="orange">
    <color rgba="1 0.3 0.1 1"/>
  </material>
  <material name="blue">
    <color rgba="0.2 0.2 1 1"/>
  </material>
  <material name="black">
    <color rgba="0 0 0 1"/>
  </material>
  <material name="grey">
    <color rgba="0.5 0.5 0.5 1"/>
  </material>
  <!-- Specify some standard inertial calculations https://en.wikipedia.org/wiki/List_of_moments_of_inertia -->
  <!-- These make use of xacro's mathematical functionality -->
  <!-- BASE LINK -->
  <link name="base_link">

    </link>
  <!-- CHASSIS LINK -->
  <joint name="chassis_joint" type="fixed">
    <parent link="base_link"/>
    <child link="chassis"/>
    <origin xyz="-0.125 0 0.012"/>
  </joint>
  <link name="chassis">
    <visual>
      <origin xyz="0.125 0 0.0325"/>
      <geometry>
        <box size="0.06 0.19 0.065"/>
      </geometry>
      <material name="white"/>
    </visual>
    <visual>
      <origin xyz="0.155 0 0.0325"/>
      <geometry>
        <cylinder length="0.065" radius="0.095"/>
      </geometry>
      <material name="white"/>
    </visual>
    <visual>
      <origin xyz="0.095 0 0.0325"/>
      <geometry>
        <cylinder length="0.065" radius="0.095"/>
      </geometry>
      <material name="white"/>
    </visual>
    <collision>
      <origin xyz="0.125 0 0.0325"/>
      <geometry>
        <box size="0.06 0.19 0.065"/>
      </geometry>
    </collision>
    <collision>
      <origin xyz="0.155 0 0.0325"/>
      <geometry>
        <cylinder length="0.065" radius="0.095"/>
      </geometry>
    </collision>
    <collision>
      <origin xyz="0.095 0 0.0325"/>
      <geometry>
        <cylinder length="0.065" radius="0.095"/>
      </geometry>
    </collision>
    <inertial>
      <origin rpy="0 0 0" xyz="0.125 0 0.0325"/>
      <mass value="0.295"/>
      <inertia ixx="0.0009913229166666666" ixy="0.0" ixz="0.0" iyy="0.0016403229166666667" iyz="0.0" izz="0.0024239166666666662"/>
    </inertial>
  </link>
  <!-- LEFT WHEEL LINK -->
  <joint name="left_wheel_joint" type="continuous">
    <parent link="base_link"/>
    <child link="left_wheel"/>
    <origin rpy="-1.5707963267948966 0 0" xyz="0 0.075 0.035"/>
    <axis xyz="0 0 1"/>
  </joint>
  <link name="left_wheel">
    <visual>
      <geometry>
        <cylinder length="0.02" radius="0.035"/>
      </geometry>
      <material name="grey"/>
    </visual>
    <collision>
      <geometry>
        <cylinder length="0.02" radius="0.035"/>
      </geometry>
    </collision>
    <inertial>
      <origin rpy="0 0 0" xyz="0 0 0"/>
      <mass value="0.045"/>
      <inertia ixx="1.5281250000000002e-05" ixy="0.0" ixz="0.0" iyy="1.5281250000000002e-05" iyz="0.0" izz="2.7562500000000002e-05"/>
    </inertial>
  </link>
  <!-- RIGHT WHEEL LINK -->
  <joint name="right_wheel_joint" type="continuous">
    <parent link="base_link"/>
    <child link="right_wheel"/>
    <origin rpy="1.5707963267948966 0 0" xyz="0 -0.075 0.035"/>
    <axis xyz="0 0 -1"/>
  </joint>
  <link name="right_wheel">
    <visual>
      <geometry>
        <cylinder length="0.02" radius="0.035"/>
      </geometry>
      <material name="grey"/>
    </visual>
    <collision>
      <geometry>
        <cylinder length="0.02" radius="0.035"/>
      </geometry>
    </collision>
    <inertial>
      <origin rpy="0 0 0" xyz="0 0 0"/>
      <mass value="0.045"/>
      <inertia ixx="1.5281250000000002e-05" ixy="0.0" ixz="0.0" iyy="1.5281250000000002e-05" iyz="0.0" izz="2.7562500000000002e-05"/>
    </inertial>
  </link>
  <!-- FRONT LEFT CASTER LINK -->
  <joint name="fl_caster_joint" type="fixed">
    <parent link="chassis"/>
    <child link="fl_caster"/>
    <origin xyz="0.225 0.03 -0.007"/>
  </joint>
  3

    
  <link name="fl_caster">
    <visual>
      <geometry>
        <sphere radius=".005"/>
      </geometry>
      <material name="grey"/>
    </visual>
    <visual>
      <origin xyz="0 0 0.00565"/>
      <geometry>
        <box size=".015 .015 .0113"/>
      </geometry>
      <material name="blue"/>
    </visual>
    <collision>
      <geometry>
        <sphere radius=".005"/>
      </geometry>
    </collision>
    <collision>
      <origin xyz="0 0 0.00565"/>
      <geometry>
        <box size=".015 .015 .0113"/>
      </geometry>
    </collision>
    <inertial>
      <origin rpy="0 0 0" xyz="0 0 0.00565"/>
      <mass value="0.001"/>
      <inertia ixx="2.9390833333333334e-08" ixy="0.0" ixz="0.0" iyy="2.9390833333333334e-08" iyz="0.0" izz="3.75e-08"/>
    </inertial>
  </link>
  <!-- FRONT RIGHT CASTER LINK -->
  <joint name="fr_caster_joint" type="fixed">
    <parent link="chassis"/>
    <child link="fr_caster"/>
    <origin xyz="0.225 -0.03 -0.007"/>
  </joint>
  3

    
  <link name="fr_caster">
    <visual>
      <geometry>
        <sphere radius=".005"/>
      </geometry>
      <material name="grey"/>
    </visual>
    <visual>
      <origin xyz="0 0 0.00565"/>
      <geometry>
        <box size=".015 .015 .0113"/>
      </geometry>
      <material name="blue"/>
    </visual>
    <collision>
      <geometry>
        <sphere radius=".005"/>
      </geometry>
    </collision>
    <collision>
      <origin xyz="0 0 0.00565"/>
      <geometry>
        <box size=".015 .015 .0113"/>
      </geometry>
    </collision>
    <inertial>
      <origin rpy="0 0 0" xyz="0 0 0.00565"/>
      <mass value="0.001"/>
      <inertia ixx="2.9390833333333334e-08" ixy="0.0" ixz="0.0" iyy="2.9390833333333334e-08" iyz="0.0" izz="3.75e-08"/>
    </inertial>
  </link>
  <!-- BACK LEFT CASTER LINK -->
  <joint name="bl_caster_joint" type="fixed">
    <parent link="chassis"/>
    <child link="bl_caster"/>
    <origin xyz="0.025 0.03 -0.007"/>
  </joint>
  3

    
  <link name="bl_caster">
    <visual>
      <geometry>
        <sphere radius=".005"/>
      </geometry>
      <material name="grey"/>
    </visual>
    <visual>
      <origin xyz="0 0 0.00565"/>
      <geometry>
        <box size=".015 .015 .0113"/>
      </geometry>
      <material name="blue"/>
    </visual>
    <collision>
      <geometry>
        <sphere radius=".005"/>
      </geometry>
    </collision>
    <collision>
      <origin xyz="0 0 0.00565"/>
      <geometry>
        <box size=".015 .015 .0113"/>
      </geometry>
    </collision>
    <inertial>
      <origin rpy="0 0 0" xyz="0 0 0.00565"/>
      <mass value="0.001"/>
      <inertia ixx="2.9390833333333334e-08" ixy="0.0" ixz="0.0" iyy="2.9390833333333334e-08" iyz="0.0" izz="3.75e-08"/>
    </inertial>
  </link>
  <!-- BACK RIGHT CASTER LINK -->
  <joint name="br_caster_joint" type="fixed">
    <parent link="chassis"/>
    <child link="br_caster"/>
    <origin xyz="0.025 -0.03 -0.007"/>
  </joint>
  <link name="br_caster">
    <visual>
      <geometry>
        <sphere radius=".005"/>
      </geometry>
      <material name="grey"/>
    </visual>
    <visual>
      <origin xyz="0 0 0.00565"/>
      <geometry>
        <box size=".015 .015 .0113"/>
      </geometry>
      <material name="blue"/>
    </visual>
    <collision>
      <geometry>
        <sphere radius=".005"/>
      </geometry>
    </collision>
    <collision>
      <origin xyz="0 0 0.00565"/>
      <geometry>
        <box size=".015 .015 .0113"/>
      </geometry>
    </collision>
    <inertial>
      <origin rpy="0 0 0" xyz="0 0 0.00565"/>
      <mass value="0.001"/>
      <inertia ixx="2.9390833333333334e-08" ixy="0.0" ixz="0.0" iyy="2.9390833333333334e-08" iyz="0.0" izz="3.75e-08"/>
    </inertial>
  </link>
</robot>
